Workbook

Sheet Dashboard
N1: Month | O1: Debits | P1: Credits | Q1: Net Flow | R1: Tx Count | S1: Avg Debit/Tx | T1: Debit Category | U1: Amount | W1: Credit Category | X1: Amount | Y1: Month | Z1: Debits | AA1: Credits | AC1: Recipient | AD1: Total (₦) | AF1: Month | AG1: Tx Count | AH1: Month | AI1: Debits | AJ1: Credits | AK1: Net Flow | AL1: Debit Category | AM1: Amount | AN1: Credit Category | AO1: Amount | AP1: Month | AQ1: Debits | AR1: Credits | AS1: Month | AT1: Debits | AU1: Credits | AV1: Credit Category | AW1: Amount
B2: WALLET TRANSACTIONS | G2: PERFORMANCE DASHBOARD | N2: =Summary!A16 -> 2025-02 | O2: =Summary!B16 -> 122020 | P2: =Summary!C16 -> 222000 | Q2: =Summary!D16 -> 99980 | R2: =Summary!E16 -> 129 | S2: =IF(R2>0,O2/R2,0) -> 945.89147 | T2: =Summary!A48 -> Transfer Out | U2: =Summary!B48 -> 3754672.6 | W2: =Summary!E48 -> Transfer In | X2: =Summary!F48 -> 4188460 | Y2: =N2 -> 2025-02 | Z2: =O2 -> 122020 | AA2: =P2 -> 222000 | AC2: T.D. Ezeuko | AD2: 1015745 | AF2: 2025-02 | AG2: 129 | AH2: 2025-02 | AI2: 122020 | AJ2: 222000 | AK2: 99980 | AL2: Transfer Out | AM2: 3754672.6 | AN2: Transfer In | AO2: 4188460 | AP2: 2025-02 | AQ2: 122020 | AR2: 222000 | AS2: 2025-02 | AT2: 122020 | AU2: 222000 | AV2: Transfer In | AW2: 4188460
B3: Tobechukwu Daniel Ezeuko • OPay Acc: 8144409727 • Feb 2025 – Mar 2026 | G3: 14 Months • 1,937 Transactions • ₦13.9M Total Volume | N3: =Summary!A17 -> 2025-03 | O3: =Summary!B17 -> 158665 | P3: =Summary!C17 -> 56000 | Q3: =Summary!D17 -> -102665 | R3: =Summary!E17 -> 55 | S3: Avg Debit/Tx | T3: =Summary!A49 -> OWealth | U3: =Summary!B49 -> 1540855.2 | W3: =Summary!E49 -> OWealth | X3: =Summary!F49 -> 2405288.5 | Y3: =N3 -> 2025-03 | Z3: =Z2+O3 -> 280685 | AA3: =AA2+P3 -> 278000 | AC3: F.C. Anekwe | AD3: 823710 | AF3: 2025-03 | AG3: 55 | AH3: 2025-03 | AI3: 158665 | AJ3: 56000 | AK3: -102665 | AL3: OWealth | AM3: 1540855.2 | AN3: OWealth | AO3: 2405288.5 | AP3: 2025-03 | AQ3: 158665 | AR3: 56000 | AS3: 2025-03 | AT3: 280685 | AU3: 278000 | AV3: OWealth | AW3: 2405288.5
N4: =Summary!A18 -> 2025-04 | O4: =Summary!B18 -> 82769 | P4: =Summary!C18 -> 76495 | Q4: =Summary!D18 -> -6274 | R4: =Summary!E18 -> 53 | S4: =IF(R4>0,O4/R4,0) -> 1561.6792 | T4: =Summary!A50 -> POS | U4: =Summary!B50 -> 903900 | W4: =Summary!E50 -> Transfer Out | X4: =Summary!F50 -> 369000 | Y4: =N4 -> 2025-04 | Z4: =Z3+O4 -> 363454 | AA4: =AA3+P4 -> 354495 | AC4: O. Moses | AD4: 150000 | AF4: 2025-04 | AG4: 53 | AH4: 2025-04 | AI4: 82769 | AJ4: 76495 | AK4: -6274 | AL4: POS | AM4: 903900 | AN4: Transfer Out | AO4: 369000 | AP4: 2025-04 | AQ4: 82769 | AR4: 76495 | AS4: 2025-04 | AT4: 363454 | AU4: 354495 | AV4: Transfer Out | AW4: 369000
N5: =Summary!A19 -> 2025-05 | O5: =Summary!B19 -> 1541451.6 | P5: =Summary!C19 -> 1541451.6 | Q5: =Summary!D19 -> 0 | R5: =Summary!E19 -> 150 | T5: =Summary!A51 -> Payment | U5: =Summary!B51 -> 607735.96 | W5: =Summary!E51 -> Reversal | X5: =Summary!F51 -> 102 | Y5: =N5 -> 2025-05 | Z5: =Z4+O5 -> 1904905.6 | AA5: =AA4+P5 -> 1895946.6 | AC5: E.S. Ehiremhen | AD5: 84000 | AF5: 2025-05 | AG5: 150 | AH5: 2025-05 | AI5: 1541451.6 | AJ5: 1541451.6 | AK5: 0 | AL5: Payment | AM5: 607735.96 | AN5: Reversal | AO5: 102 | AP5: 2025-05 | AQ5: 1541451.6 | AR5: 1541451.6 | AS5: 2025-05 | AT5: 1904905.6 | AU5: 1895946.6 | AV5: Reversal | AW5: 102
B6: TOTAL DEBITS | D6: TOTAL CREDITS | G6: NET FLOW | I6: AVG MONTHLY VOLUME | N6: =Summary!A20 -> 2025-06 | O6: =Summary!B20 -> 741651 | P6: =Summary!C20 -> 741651 | Q6: =Summary!D20 -> 0 | R6: =Summary!E20 -> 248 | T6: =Summary!A52 -> Other | U6: =Summary!B52 -> 110308.25 | Y6: =N6 -> 2025-06 | Z6: =Z5+O6 -> 2646556.6 | AA6: =AA5+P6 -> 2637597.6 | AC6: O. Rafiu | AD6: 79000 | AF6: 2025-06 | AG6: 248 | AH6: 2025-06 | AI6: 741651 | AJ6: 741651 | AK6: 0 | AL6: Other | AM6: 110308.25 | AP6: 2025-06 | AQ6: 741651 | AR6: 741651 | AS6: 2025-06 | AT6: 2646556.6 | AU6: 2637597.6
B7: =Summary!B8 -> 6970809.5 | D7: =Summary!B9 -> 6962850.5 | G7: =D7-B7 -> -7959 | I7: =(B7+D7)/14 -> 995261.43 | N7: =Summary!A21 -> 2025-07 | O7: =Summary!B21 -> 295507.5 | P7: =Summary!C21 -> 295507.5 | Q7: =Summary!D21 -> 0 | R7: =Summary!E21 -> 132 | T7: =Summary!A53 -> Airtime/Data | U7: =Summary!B53 -> 56337.5 | Y7: =N7 -> 2025-07 | Z7: =Z6+O7 -> 2942064.1 | AA7: =AA6+P7 -> 2933105.1 | AC7: A.B. Emmanson | AD7: 74000 | AF7: 2025-07 | AG7: 132 | AH7: 2025-07 | AI7: 295507.5 | AJ7: 295507.5 | AK7: 0 | AL7: Airtime/Data | AM7: 56337.5 | AP7: 2025-07 | AQ7: 295507.5 | AR7: 295507.5 | AS7: 2025-07 | AT7: 2942064.1 | AU7: 2933105.1
B8: =Summary!B10&" transactions" -> 1135 transactions | D8: =Summary!B11&" transactions" -> 802 transactions | G8: debit surplus | I8: ="avg "&TEXT(Summary!B12/14,"#,##0")&" txs/month" -> avg 138 txs/month | N8: =Summary!A22 -> 2025-08 | O8: =Summary!B22 -> 220352 | P8: =Summary!C22 -> 218352 | Q8: =Summary!D22 -> -2000 | R8: =Summary!E22 -> 135 | Y8: =N8 -> 2025-08 | Z8: =Z7+O8 -> 3162416.1 | AA8: =AA7+P8 -> 3151457.1 | AC8: M.B. Isah | AD8: 45000 | AF8: 2025-08 | AG8: 135 | AH8: 2025-08 | AI8: 220352 | AJ8: 218352 | AK8: -2000 | AP8: 2025-08 | AQ8: 220352 | AR8: 218352 | AS8: 2025-08 | AT8: 3162416.1 | AU8: 3151457.1
N9: =Summary!A23 -> 2025-09 | O9: =Summary!B23 -> 548023.5 | P9: =Summary!C23 -> 548023.5 | Q9: =Summary!D23 -> 0 | R9: =Summary!E23 -> 200 | Y9: =N9 -> 2025-09 | Z9: =Z8+O9 -> 3710439.6 | AA9: =AA8+P9 -> 3699480.6 | AC9: E.E. Christopher | AD9: 43000 | AF9: 2025-09 | AG9: 200 | AH9: 2025-09 | AI9: 548023.5 | AJ9: 548023.5 | AK9: 0 | AP9: 2025-09 | AQ9: 548023.5 | AR9: 548023.5 | AS9: 2025-09 | AT9: 3710439.6 | AU9: 3699480.6
N10: =Summary!A24 -> 2025-10 | O10: =Summary!B24 -> 527086 | P10: =Summary!C24 -> 527086 | Q10: =Summary!D24 -> 0 | R10: =Summary!E24 -> 165 | Y10: =N10 -> 2025-10 | Z10: =Z9+O10 -> 4237525.6 | AA10: =AA9+P10 -> 4226566.6 | AC10: J.A. Okechukwu | AD10: 31500 | AF10: 2025-10 | AG10: 165 | AH10: 2025-10 | AI10: 527086 | AJ10: 527086 | AK10: 0 | AP10: 2025-10 | AQ10: 527086 | AR10: 527086 | AS10: 2025-10 | AT10: 4237525.6 | AU10: 4226566.6
B11: Monthly Cash Flow Trend | G11: Transaction Volume | N11: =Summary!A25 -> 2025-11 | O11: =Summary!B25 -> 384460 | P11: =Summary!C25 -> 384460 | Q11: =Summary!D25 -> 0 | R11: =Summary!E25 -> 176 | Y11: =N11 -> 2025-11 | Z11: =Z10+O11 -> 4621985.6 | AA11: =AA10+P11 -> 4611026.6 | AC11: B.A. Rufai | AD11: 30010 | AF11: 2025-11 | AG11: 176 | AH11: 2025-11 | AI11: 384460 | AJ11: 384460 | AK11: 0 | AP11: 2025-11 | AQ11: 384460 | AR11: 384460 | AS11: 2025-11 | AT11: 4621985.6 | AU11: 4611026.6
B12: Debits vs Credits over 14 months | G12: Monthly transaction count | N12: =Summary!A26 -> 2025-12 | O12: =Summary!B26 -> 993216.96 | P12: =Summary!C26 -> 993216.96 | Q12: =Summary!D26 -> 0 | R12: =Summary!E26 -> 109 | Y12: =N12 -> 2025-12 | Z12: =Z11+O12 -> 5615202.5 | AA12: =AA11+P12 -> 5604243.5 | AF12: 2025-12 | AG12: 109 | AH12: 2025-12 | AI12: 993216.96 | AJ12: 993216.96 | AK12: 0 | AP12: 2025-12 | AQ12: 993216.96 | AR12: 993216.96 | AS12: 2025-12 | AT12: 5615202.5 | AU12: 5604243.5
N13: =Summary!A27 -> 2026-01 | O13: =Summary!B27 -> 712898 | P13: =Summary!C27 -> 712898 | Q13: =Summary!D27 -> 0 | R13: =Summary!E27 -> 190 | Y13: =N13 -> 2026-01 | Z13: =Z12+O13 -> 6328100.5 | AA13: =AA12+P13 -> 6317141.5 | AF13: 2026-01 | AG13: 190 | AH13: 2026-01 | AI13: 712898 | AJ13: 712898 | AK13: 0 | AP13: 2026-01 | AQ13: 712898 | AR13: 712898 | AS13: 2026-01 | AT13: 6328100.5 | AU13: 6317141.5
N14: =Summary!A28 -> 2026-02 | O14: =Summary!B28 -> 580597 | P14: =Summary!C28 -> 580597 | Q14: =Summary!D28 -> 0 | R14: =Summary!E28 -> 168 | Y14: =N14 -> 2026-02 | Z14: =Z13+O14 -> 6908697.5 | AA14: =AA13+P14 -> 6897738.5 | AF14: 2026-02 | AG14: 168 | AH14: 2026-02 | AI14: 580597 | AJ14: 580597 | AK14: 0 | AP14: 2026-02 | AQ14: 580597 | AR14: 580597 | AS14: 2026-02 | AT14: 6908697.5 | AU14: 6897738.5
N15: =Summary!A29 -> 2026-03 | O15: =Summary!B29 -> 65112 | P15: =Summary!C29 -> 65112 | Q15: =Summary!D29 -> 0 | R15: =Summary!E29 -> 27 | Y15: =N15 -> 2026-03 | Z15: =Z14+O15 -> 6973809.5 | AA15: =AA14+P15 -> 6962850.5 | AF15: 2026-03 | AG15: 27 | AH15: 2026-03 | AI15: 65112 | AJ15: 65112 | AK15: 0 | AP15: 2026-03 | AQ15: 65112 | AR15: 65112 | AS15: 2026-03 | AT15: 6973809.5 | AU15: 6962850.5
B30: Spending Breakdown | G30: Income Sources
B31: Debit categories by amount | G31: Credit categories by amount
B49: Debit vs Credit Comparison | G49: Cumulative Cash Flow
B50: Monthly inflows vs outflows (₦) | G50: Running total of debits vs credits (₦)

Sheet Summary
A1: OPAY FINANCIAL STATEMENT
A2: Period: 01 Feb 2025-07 Mar 2026 | TOBECHUKWU DANIEL EZEUKO (Acc: 8144409727)
A4: ACCOUNT OVERVIEW
A5: Metric | B5: Wallet Account | C5: Savings Account
A6: Opening Balance (₦) | B6: 7959 | C6: 0
A7: Closing Balance (₦) | B7: 0 | C7: 31514.84
A8: Total Debit (₦) | B8: 6970809.5 | C8: 2405288.5
A9: Total Credit (₦) | B9: 6962850.5 | C9: 2436803.4
A10: Debit Count | B10: 1135 | C10: 692
A11: Credit Count | B11: 802 | C11: 374
A12: Total Transactions | B12: 1937 | C12: 1066
A14: WALLET — MONTHLY TRANSACTION SUMMARY
A15: Month | B15: Total Debit (₦) | C15: Total Credit (₦) | D15: Net (₦) | E15: Tx Count
A16: 2025-02 | B16: 122020 | C16: 222000 | D16: 99980 | E16: 129
A17: 2025-03 | B17: 158665 | C17: 56000 | D17: -102665 | E17: 55
A18: 2025-04 | B18: 82769 | C18: 76495 | D18: -6274 | E18: 53
A19: 2025-05 | B19: 1541451.6 | C19: 1541451.6 | D19: 0 | E19: 150
A20: 2025-06 | B20: 741651 | C20: 741651 | D20: 0 | E20: 248
A21: 2025-07 | B21: 295507.5 | C21: 295507.5 | D21: 0 | E21: 132
A22: 2025-08 | B22: 220352 | C22: 218352 | D22: -2000 | E22: 135
A23: 2025-09 | B23: 548023.5 | C23: 548023.5 | D23: 0 | E23: 200
A24: 2025-10 | B24: 527086 | C24: 527086 | D24: 0 | E24: 165
A25: 2025-11 | B25: 384460 | C25: 384460 | D25: 0 | E25: 176
A26: 2025-12 | B26: 993216.96 | C26: 993216.96 | D26: 0 | E26: 109
A27: 2026-01 | B27: 712898 | C27: 712898 | D27: 0 | E27: 190
... A29: 2026-03 | B29: 65112 | C29: 65112 | D29: 0 | E29: 27
A31: SAVINGS — MONTHLY TRANSACTION SUMMARY
A32: Month | B32: Total Debit (₦) | C32: Total Credit (₦) | D32: Net (₦) | E32: Tx Count
A33: 2025-04 | B33: 2995 | C33: 11390.76 | D33: 8395.76 | E33: 4
A34: 2025-05 | B34: 209741.58 | C34: 277674.13 | D34: 67932.55 | E34: 91
A35: 2025-06 | B35: 397351 | C35: 325916.26 | D35: -71434.74 | E35: 134
A36: 2025-07 | B36: 107507.5 | C36: 103992.52 | D36: -3514.98 | E36: 89
A37: 2025-08 | B37: 45852 | C37: 46680.92 | D37: 828.92 | E37: 83
A38: 2025-09 | B38: 204921.5 | C38: 210920.57 | D38: 5999.07 | E38: 119
A39: 2025-10 | B39: 144036 | C39: 164371.57 | D39: 20335.57 | E39: 99
A40: 2025-11 | B40: 135160 | C40: 110912.51 | D40: -24247.49 | E40: 110
A41: 2025-12 | B41: 233216.96 | C41: 320390.71 | D41: 87173.75 | E41: 79
A42: 2026-01 | B42: 599898 | C42: 548190.81 | D42: -51707.19 | E42: 126
A43: 2026-02 | B43: 299497 | C43: 281334.3 | D43: -18162.7 | E43: 112
A44: 2026-03 | B44: 25112 | C44: 35028.32 | D44: 9916.32 | E44: 20
...

Sheet Wallet Transactions
A1: # | B1: Trans Date | C1: Value Date | D1: Description | E1: Debit (₦) | F1: Credit (₦) | G1: Balance After (₦) | H1: Channel | I1: Transaction Type | J1: Category | K1: Month-Year | L1: Transaction Reference
A2: 1 | B2: 45689.38 | C2: 45689 | D2: Transfer to POS Transfer-FELICIA IDIKWU | MONIE POINT | 5801641866 | E2: 600 | F2: 0 | G2: 7359 | H2: Mobile | I2: Debit | J2: Transfer Out | K2: 2025-02 | L2: 100004250201080757126420099842
A3: 2 | B3: 45689.923 | C3: 45689 | D3: Transfer to AKASE RUTH | Fidelity Bank | 6160298120 | E3: 500 | F3: 0 | G3: 6859 | H3: Mobile | I3: Debit | J3: Transfer Out | K3: 2025-02 | L3: 100004250201210854126471763011
A4: 3 | B4: 45689.96 | C4: 45689 | D4: Transfer to OLUWASHEDA TAYE SUNDAY | Guaranty Trust Bank | 0618667245 | E4: 800 | F4: 0 | G4: 6059 | H4: Mobile | I4: Debit | J4: Transfer Out | K4: 2025-02 | L4: 100004250201220300126473094651
A5: 4 | B5: 45690.437 | C5: 45690 | D5: Transfer to SAS ENTERPRISE | MONIE POINT | 8313484172 | E5: 500 | F5: 0 | G5: 5559 | H5: Mobile | I5: Debit | J5: Transfer Out | K5: 2025-02 | L5: 100004250202092923126485190876
A6: 5 | B6: 45690.659 | C6: 45690 | D6: Transfer to NDORENYIN UYOBONG UMOETUK | OPay | 8098764551 | E6: 2250 | F6: 0 | G6: 3309 | H6: Mobile | I6: Debit | J6: Transfer Out | K6: 2025-02 | L6: 250202010100073474572450
A7: 6 | B7: 45691.37 | C7: 45691 | D7: Transfer to SIDIDEB GLOBAL SERVICES | OPay | 8053308586 | E7: 200 | F7: 0 | G7: 3109 | H7: Mobile | I7: Debit | J7: Transfer Out | K7: 2025-02 | L7: 250203180100081968455460
A8: 7 | B8: 45691.397 | C8: 45691 | D8: Transfer to JUSTIN AMOS | OPay | 8063625287 | E8: 400 | F8: 0 | G8: 2709 | H8: Mobile | I8: Debit | J8: Transfer Out | K8: 2025-02 | L8: 250203010100082575100274
A9: 8 | B9: 45691.565 | C9: 45691 | D9: Transfer to POS Transfer-EMMANUEL CHINONYE NNABU | MONIE POINT | 5870533604 | E9: 1600 | F9: 0 | G9: 1109 | H9: Mobile | I9: Debit | J9: Transfer Out | K9: 2025-02 | L9: 100004250203123419126549790800
A10: 9 | B10: 45691.795 | C10: 45691 | D10: Transfer to IYANU KIRK OJO | OPay | 8164102558 | E10: 200 | F10: 0 | G10: 909 | H10: Mobile | I10: Debit | J10: Transfer Out | K10: 2025-02 | L10: 250203010100091084166497
A11: 10 | B11: 45691.799 | C11: 45691 | D11: Transfer from TOBECHUKWU DANIEL EZEUKO | Wema Bank PLC | 041****864 | Opay-945 Transfer to Opay Digital Services Limited | E11: 0 | F11: 7000 | G11: 7909 | H11: Mobile | I11: Credit | J11: Transfer Out | K11: 2025-02 | L11: 000017250203191111550171757604
A12: 11 | B12: 45691.909 | C12: 45691 | D12: Transfer to ADAMA IBRAHIM | Momo Payment Service Bank | 7043786615 | E12: 300 | F12: 0 | G12: 7609 | H12: Mobile | I12: Debit | J12: Transfer Out | K12: 2025-02 | L12: 100004250203204838126584971078
A13: 12 | B13: 45692.543 | C13: 45692 | D13: Transfer to POS Transfer- EGBO MAUREEN OGECHUKWU | MONIE POINT | 5932663494 | E13: 1300 | F13: 0 | G13: 6309 | H13: Mobile | I13: Debit | J13: Transfer Out | K13: 2025-02 | L13: 100004250204120243126611719778
... A1938: 1937 | B1938: 46088.718 | C1938: 46088 | D1938: Transfer to OUPS EAGLE INDUSTRIES INT'L | OPay | 8086908033 | E1938: 4000 | F1938: 0 | G1938: 0 | H1938: Mobile | I1938: Debit | J1938: Transfer Out | K1938: 2026-03 | L1938: 260307010100882320662709

Sheet Savings Transactions
A1: # | B1: Trans Date | C1: Value Date | D1: Description | E1: Debit (₦) | F1: Credit (₦) | G1: Balance After (₦) | H1: Channel | I1: Transaction Type | J1: Category | K1: Month-Year | L1: Transaction Reference
A2: 1 | B2: 45774.528 | C2: 45774 | D2: OWealth Deposit(from Targets) | E2: 0 | F2: 11385 | G2: 11385 | H2: Mobile | I2: Credit | J2: OWealth | K2: 2025-04 | L2: 25042799tLtt2gVzbaRg71H0ZrhL0
A3: 2 | B3: 45775.379 | C3: 45775 | D3: OWealth Withdrawal(Transaction Payment) | E3: 2995 | F3: 0 | G3: 8390 | H3: Mobile | I3: Debit | J3: OWealth | K3: 2025-04 | L3: 250428010200415812394286
A4: 3 | B4: 45776.162 | C4: 45776 | D4: OWealth Interest Earned | E4: 0 | F4: 2.88 | G4: 8392.88 | H4: Mobile | I4: Credit | J4: OWealth | K4: 2025-04 | L4: 25042999bfXJxa54weRWhLaYHTY3f
A5: 4 | B5: 45777.151 | C5: 45777 | D5: OWealth Interest Earned | E5: 0 | F5: 2.88 | G5: 8395.76 | H5: Mobile | I5: Credit | J5: OWealth | K5: 2025-04 | L5: 2504309965BXkEiIKYxbqn2mITWG06
A6: 5 | B6: 45778.155 | C6: 45778 | D6: OWealth Interest Earned | E6: 0 | F6: 2.88 | G6: 8398.64 | H6: Mobile | I6: Credit | J6: OWealth | K6: 2025-05 | L6: 2505019952CTSz6HhondHVpSBDguBa
A7: 6 | B7: 45778.694 | C7: 45778 | D7: OWealth Withdrawal(Transaction Payment) | E7: 350 | F7: 0 | G7: 8048.64 | H7: Mobile | I7: Debit | J7: OWealth | K7: 2025-05 | L7: 250501010200473590162763
A8: 7 | B8: 45778.719 | C8: 45778 | D8: OWealth Withdrawal(Transaction Payment) | E8: 2000 | F8: 0 | G8: 6048.64 | H8: Mobile | I8: Debit | J8: OWealth | K8: 2025-05 | L8: 250501010200474102985426
A9: 8 | B9: 45779.146 | C9: 45779 | D9: OWealth Interest Earned | E9: 0 | F9: 2.07 | G9: 6050.71 | H9: Mobile | I9: Credit | J9: OWealth | K9: 2025-05 | L9: 250502994AHSF5xdIKvv2xHpx9Zsqr
A10: 9 | B10: 45779.392 | C10: 45779 | D10: OWealth Withdrawal(Transaction Payment) | E10: 750 | F10: 0 | G10: 5300.71 | H10: Mobile | I10: Debit | J10: OWealth | K10: 2025-05 | L10: 250502010200484178199935
A11: 10 | B11: 45779.502 | C11: 45779 | D11: OWealth Withdrawal(Transaction Payment) | E11: 3100 | F11: 0 | G11: 2200.71 | H11: Mobile | I11: Debit | J11: OWealth | K11: 2025-05 | L11: 250502010200486751117256
A12: 11 | B12: 45780.142 | C12: 45780 | D12: OWealth Interest Earned | E12: 0 | F12: 0.75 | G12: 2201.46 | H12: Mobile | I12: Credit | J12: OWealth | K12: 2025-05 | L12: 250503997N2P1rwDVQX73BxEwijKsW
A13: 12 | B13: 45781.146 | C13: 45781 | D13: OWealth Interest Earned | E13: 0 | F13: 0.75 | G13: 2202.21 | H13: Mobile | I13: Credit | J13: OWealth | K13: 2025-05 | L13: 250504994m8dH10ZPO7gjxzGcF2xJ7
... A1067: 1066 | B1067: 46088.718 | C1067: 46088 | D1067: OWealth Withdrawal(Transaction Payment) | E1067: 4000 | F1067: 0 | G1067: 31514.84 | H1067: Mobile | I1067: Debit | J1067: OWealth | K1067: 2026-03 | L1067: 260307010201882320943936

Sheet Explanation
A1: PROJECT README OPay Personal Financial Analytics Dashboard Tobechukwu Daniel Ezeuko
A5: ABOUT THIS PROJECT
A7: This project is a personal financial analytics dashboard built from a raw OPay bank statement covering 14 months of real transaction data. It was designed as a portfolio project to demonstrate practical data skills — from raw data cleaning to insight generation and dashboard presentation.
A9: The goal was simple: take an unstructured PDF bank statement, convert it into a structured dataset, and extract meaningful patterns about personal financial behaviour.
A13: DATA SOURCE
A15: Source: OPay Digital Services Limited — Personal Account Statement Account Name: Tobechukwu Daniel Ezeuko Account Number: 8144409727 Period Covered: 01 February 2025 – 07 March 2026 Data Type: Real personal transaction data (sanitized for portfolio use)
A19: SCOPE OF ANALYSIS
A21: Two accounts were analyzed:
A23: 1. Wallet Account — Primary transaction account used for daily transfers, payments, and spending
A24: 2. Savings Account (OWealth) — Linked savings and investment account with daily interest accruals
A26: Combined, the dataset covers 3,003 transactions and approximately ₦13.9 million in total transaction volume across 14 months.
A30: TOOLS USED
... A42: WORKBOOK STRUCTURE
A44: Sheet | B44: Description
A45: Dashboard | B45: Visual summary — KPI cards, monthly trends, spending and income breakdowns, top recipients
A46: Summary | B46: Consolidated monthly figures for both wallet and savings accounts
A47: Wallet Transactions | B47: Full cleaned transaction log for the OPay Wallet account (1,937 rows)
A48: Savings Transactions | B48: Full cleaned transaction log for the OWealth Savings account (1,066 rows)
A49: README | B49: Project documentation (this sheet)
A52: KEY METRICS
A54: Metric | B54: Value
A55: Total Period | B55: 14 months
A56: Total Transactions | B56: 3003
A57: Total Volume (Wallet) | B57: ₦13,933,660.08
A58: Total Debits (Wallet) | B58: ₦6,970,809.54
A59: Total Credits (Wallet) | B59: ₦6,962,850.54
A60: Net Cash Flow (Wallet) | B60: -₦7,959.00
A61: Average Monthly Volume | B61: ~₦995,261
A62: Average Transactions/Month | B62: ~138
A63: Savings Closing Balance | B63: ₦31,514.84
A64: Interest Earned (OWealth) | B64: ₦3,172+
A67: CATEGORIES USED
A69: Debit Categories: Transfer Out, OWealth (savings deposit), POS, Payment, Airtime/Data, Other
A71: Credit Categories: Transfer In, OWealth (savings return), Transfer Out (reversals), Reversal
A73: Categories were assigned based on transaction description keywords and manually reviewed for accuracy.
A77: KEY FINDINGS
A79: 1. The wallet functions primarily as a transit account — from May 2025 onward, net monthly cash flow was consistently ₦0, indicating money moves through rather than accumulates.
A81: 2. Outward transfers to other people represent 53.9% of all debit spending — the dominant financial behaviour across the period.
A83: 3. Over ₦1 million was transferred to the account holder's own external bank accounts, reflecting deliberate fund distribution across multiple accounts.
A85: 4. June 2025 was the most active month with 248 transactions (nearly 8 per day). May 2025 recorded the highest transaction volume at ₦1.54 million.
...
